<?xml version="1.0" ?>
<!-- =================================================================================== -->
<!-- |    This document was autogenerated by xacro from daedalus.xacro                 | -->
<!-- |    EDITING THIS FILE BY HAND IS NOT RECOMMENDED                                 | -->
<!-- =================================================================================== -->
<robot name="daedalus" xmlns:xacro="http://www.ros.org/wiki/xacro">
  <!--xacro:property name="const" value="0.2" /-->
  <!-- <xacro:property name="const" value="0.01" /> -->
  <gazebo>
    <plugin filename="libgazebo_ros_control.so" name="gazebo_ros_control">
      <robotNamespace>/daedalus</robotNamespace>
    </plugin>
  </gazebo>
  <!-- ros_control plugin -->
  <material name="black">
    <color rgba="0.0 0.0 0.0 1.0"/>
  </material>
  <material name="blue">
    <color rgba="0.0 0.0 0.8 1.0"/>
  </material>
  <material name="green">
    <color rgba="0.0 0.8 0.0 1.0"/>
  </material>
  <material name="grey">
    <color rgba="0.2 0.2 0.2 1.0"/>
  </material>
  <material name="orange">
    <color rgba="1.0 0.423529411765 0.0392156862745 1.0"/>
  </material>
  <material name="brown">
    <color rgba="0.870588235294 0.811764705882 0.764705882353 1.0"/>
  </material>
  <material name="red">
    <color rgba="0.8 0.0 0.0 1.0"/>
  </material>
  <material name="white">
    <color rgba="1.0 1.0 1.0 1.0"/>
  </material>
  <!--xacro:property name="scale" value="0.01" /-->
  <!--xacro:property name="scale" value="0" /-->
  <!-- <xacro:property name="m0" value="1" />
  <xacro:property name="m1" value="1" />
  <xacro:property name="m2" value="1" />
  <xacro:property name="m3" value="1" />
  <xacro:property name="m4" value="1" />
  <xacro:property name="m5" value="1" /> -->
  <link name="root"/>
  <virtual_joint child_link="root" name="v_root" parent_frame="world" type="fixed"/>
  <link name="frame">
    <inertial>
      <origin rpy="0 0 0" xyz="0 0 0"/>
      <mass value="2.40264202"/>
      <inertia ixx="0.000367" ixy="0" ixz="0" iyy="0.000630" iyz="0" izz="0.000862"/>
      <!-- <inertia ixx="0" ixy="0" ixz="0" iyy="0" iyz="0" izz="0"/> -->
    </inertial>
    <collision>
      <origin rpy="0 0 0" xyz="0 0 0"/>
      <geometry>
        <box size="0.28 0.125 0.06"/>
      </geometry>
    </collision>
    <!--       <visual name="visual">
        <origin xyz="0 0 0" rpy="0 0 0"/>
        <geometry>
          <mesh filename="package://daedalus_description/meshes/FRAME_new.dae"/>

        </geometry>
      </visual>
 -->
    <visual>
      <origin rpy="0 0 0" xyz="0 0 0"/>
      <geometry>
        <box size="0.28 0.125 0.06"/>
      </geometry>
    </visual>
  </link>
  <gazebo reference="frame">
    <!-- <mu1>0.2</mu1>
		<mu2>0.2</mu2> -->
    <material>Gazebo/Black</material>
  </gazebo>
  <joint name="r_root" type="fixed">
    <child link="frame"/>
    <parent link="root"/>
  </joint>
  <!-- Link0 -->
  <gazebo reference="leg1link0">
    <mu1>0.2</mu1>
    <mu2>0.2</mu2>
    <material>Gazebo/Black</material>
  </gazebo>
  <!-- Link1 -->
  <gazebo reference="leg1link1">
    <material>Gazebo/Orange</material>
  </gazebo>
  <!-- Link2 -->
  <gazebo reference="leg1link2">
    <mu1>0.2</mu1>
    <mu2>0.2</mu2>
    <material>Gazebo/Black</material>
  </gazebo>
  <!-- Link3 -->
  <gazebo reference="leg1link3">
    <mu1>0.2</mu1>
    <mu2>0.2</mu2>
    <material>Gazebo/Orange</material>
  </gazebo>
  <!-- Link4 -->
  <gazebo reference="leg1link4">
    <mu1>0.2</mu1>
    <mu2>0.2</mu2>
    <material>Gazebo/Black</material>
  </gazebo>
  <!-- Link5 -->
  <gazebo reference="leg1link5">
    <mu1>0.2</mu1>
    <mu2>0.2</mu2>
    <material>Gazebo/Orange</material>
  </gazebo>
  <link name="leg1link0">
    <self_collide>1</self_collide>
    <inertial>
      <origin rpy="0 0 0" xyz="0 0 0"/>
      <mass value="0.47264202"/>
      <inertia ixx="4.39200522187e-05" ixy="0" ixz="0" iyy="5.31290419486e-05" iyz="0" izz="5.01277802462e-05"/>
    </inertial>
    <collision name="collision">
      <origin rpy="0 0 0" xyz="0 0 0"/>
      <geometry>
        <mesh filename="package://daedalus_description/meshes/link0.dae"/>
      </geometry>
    </collision>
    <visual name="visual">
      <origin rpy="0 0 0" xyz="0 0 0"/>
      <geometry>
        <mesh filename="package://daedalus_description/meshes/link0.dae"/>
      </geometry>
    </visual>
  </link>
  <link name="leg1link1">
    <self_collide>1</self_collide>
    <inertial>
      <origin rpy="0 0 0" xyz="-0.0236 0 0"/>
      <mass value="0.62343552"/>
      <inertia ixx="0.000160071617099" ixy="2.87852024859e-07" ixz="2.50811887715e-05" iyy="0.000174781160491" iyz="-1.05497821038e-06" izz="7.16466070774e-05"/>
    </inertial>
    <collision name="collision">
      <origin rpy="0 0 0" xyz="-0.0236 0 0"/>
      <geometry>
        <mesh filename="package://daedalus_description/meshes/link1.dae"/>
      </geometry>
    </collision>
    <visual name="visual">
      <origin rpy="0 0 0" xyz="-0.0236 0 0"/>
      <geometry>
        <mesh filename="package://daedalus_description/meshes/link1.dae"/>
      </geometry>
    </visual>
  </link>
  <link name="leg1link2">
    <self_collide>1</self_collide>
    <inertial>
      <origin rpy="0 0 0" xyz="0 0.0371 -0.0015"/>
      <mass value="0.73212067"/>
      <inertia ixx="0.000225692997965" ixy="0" ixz="0" iyy="0.00010348394328" iyz="-4.53711798338e-06" izz="0.000234791733618"/>
    </inertial>
    <collision name="collision">
      <origin rpy="0 0 0" xyz="0 0.0371 -0.0015"/>
      <geometry>
        <mesh filename="package://daedalus_description/meshes/link2.dae"/>
      </geometry>
    </collision>
    <visual name="visual">
      <origin rpy="0 0 0" xyz="0 0.0371 -0.0015"/>
      <geometry>
        <mesh filename="package://daedalus_description/meshes/link2.dae"/>
      </geometry>
    </visual>
  </link>
  <link name="leg1link3">
    <self_collide>1</self_collide>
    <inertial>
      <origin rpy="0 0 0" xyz=" 0 -0.0041 -0.0371"/>
      <mass value="0.43109013"/>
      <inertia ixx="7.65993537709e-05" ixy="0" ixz="0" iyy="8.9932317097e-05" iyz="-6.34504749832e-06" izz="2.57010322713e-05"/>
    </inertial>
    <collision name="collision">
      <origin rpy="0 0 0" xyz="0 -0.0041 -0.0371"/>
      <geometry>
        <mesh filename="package://daedalus_description/meshes/link3.dae"/>
      </geometry>
    </collision>
    <visual name="visual">
      <origin rpy="0 0 0" xyz="0 -0.0041 -0.0371"/>
      <geometry>
        <mesh filename="package://daedalus_description/meshes/link3.dae"/>
      </geometry>
    </visual>
  </link>
  <link name="leg1link4">
    <self_collide>1</self_collide>
    <inertial>
      <origin rpy="0 0 0" xyz="0.0002  -0.0233 -0.0124"/>
      <mass value="0.79043472"/>
      <inertia ixx="0.000481530525726" ixy="1.06797010376e-05" ixz="-4.12651188184e-06" iyy="0.000185315488282" iyz="0.000142151873316" izz="0.000404192441138"/>
    </inertial>
    <collision name="collision">
      <origin rpy="0 0 0" xyz="0.0002  -0.0233 -0.0124"/>
      <geometry>
        <mesh filename="package://daedalus_description/meshes/link4.dae"/>
      </geometry>
    </collision>
    <visual name="visual">
      <origin rpy="0 0 0" xyz="0.0002  -0.0233 -0.0124"/>
      <geometry>
        <mesh filename="package://daedalus_description/meshes/link4.dae"/>
      </geometry>
    </visual>
  </link>
  <link name="leg1link5">
    <self_collide>1</self_collide>
    <inertial>
      <origin rpy="0 0 0" xyz="-0.0006 -0.0009 -0.0311"/>
      <mass value="0.65552696"/>
      <inertia ixx="0.000252796206096" ixy="-1.46765275547e-07" ixz="-8.81848495125e-06" iyy="0.000187690504097" iyz="-2.34414867631e-06" izz="0.000221889194174"/>
    </inertial>
    <collision name="collision">
      <surface>
        <friction>
          <ode>
            <mu>100</mu>
            <mu2>10</mu2>
          </ode>
        </friction>
      </surface>
      <origin rpy="0 0 0" xyz="-0.0006 -0.0009 -0.0311"/>
      <geometry>
        <mesh filename="package://daedalus_description/meshes/link5.dae"/>
      </geometry>
    </collision>
    <visual name="visual">
      <origin rpy="0 0 0" xyz="-0.0006 -0.0009 -0.0311"/>
      <geometry>
        <mesh filename="package://daedalus_description/meshes/link5.dae"/>
      </geometry>
    </visual>
  </link>
  <!-- -->
  <joint name="leg1joint0" type="fixed">
    <child link="leg1link0"/>
    <parent link="frame"/>
    <origin rpy="0 0 3.14" xyz="0.14 0.0625 0"/>
    <axis xyz="1 0 0"/>
  </joint>
  <joint name="leg1joint1" type="revolute">
    <origin rpy="0 0 0" xyz="-0.0249 0 0.0205"/>
    <child link="leg1link1"/>
    <parent link="leg1link0"/>
    &quot;
      
    <axis xyz="0 0 -1"/>
    <limit effort="100" lower="-1.57" upper="1.57" velocity="10"/>
  </joint>
  <joint name="leg1joint2" type="revolute">
    <origin rpy="1.570795 0 3.14159" xyz="-0.0309 0.0002 0.0381"/>
    <child link="leg1link2"/>
    <parent link="leg1link1"/>
    <axis xyz="-1.0 0 0"/>
    <limit effort="100" lower="-1.57" upper="1.57" velocity="10"/>
  </joint>
  <joint name="leg1joint3" type="revolute">
    <origin rpy="0 0 0" xyz="0 0.0564 -0.0208"/>
    <child link="leg1link3"/>
    <parent link="leg1link2"/>
    <axis xyz="1.0 0 0"/>
    <limit effort="100" lower="-1.57" upper="1.57" velocity="10"/>
  </joint>
  <joint name="leg1joint4" type="revolute">
    <origin rpy="-0.7853975 0 0" xyz="0 -0.0171 -0.0742"/>
    <child link="leg1link4"/>
    <parent link="leg1link3"/>
    <axis xyz="1.0 0 0"/>
    <limit effort="100" lower="-1.57" upper="1.57" velocity="10"/>
  </joint>
  <joint name="leg1joint5" type="revolute">
    <origin rpy="0 0 0" xyz="-0.0004 -0.0411 -0.0248"/>
    <child link="leg1link5"/>
    <parent link="leg1link4"/>
    <axis xyz="0 1 0"/>
    <limit effort="100" lower="-1.57" upper="1.57" velocity="10"/>
  </joint>
  <!-- -->
  <transmission name="tran1">
    <type>transmission_interface/SimpleTransmission</type>
    <joint name="leg1joint1">
      <hardwareInterface>EffortJointInterface</hardwareInterface>
    </joint>
    <actuator name="motor1">
      <hardwareInterface>EffortJointInterface</hardwareInterface>
      <mechanicalReduction>1</mechanicalReduction>
    </actuator>
  </transmission>
  <transmission name="tran2">
    <type>transmission_interface/SimpleTransmission</type>
    <joint name="leg1joint2">
      <hardwareInterface>EffortJointInterface</hardwareInterface>
    </joint>
    <actuator name="motor2">
      <hardwareInterface>EffortJointInterface</hardwareInterface>
      <mechanicalReduction>1</mechanicalReduction>
    </actuator>
  </transmission>
  <transmission name="tran3">
    <type>transmission_interface/SimpleTransmission</type>
    <joint name="leg1joint3">
      <hardwareInterface>EffortJointInterface</hardwareInterface>
    </joint>
    <actuator name="motor3">
      <hardwareInterface>EffortJointInterface</hardwareInterface>
      <mechanicalReduction>1</mechanicalReduction>
    </actuator>
  </transmission>
  <transmission name="tran4">
    <type>transmission_interface/SimpleTransmission</type>
    <joint name="leg1joint4">
      <hardwareInterface>EffortJointInterface</hardwareInterface>
    </joint>
    <actuator name="motor4">
      <hardwareInterface>EffortJointInterface</hardwareInterface>
      <mechanicalReduction>1</mechanicalReduction>
    </actuator>
  </transmission>
  <transmission name="tran5">
    <type>transmission_interface/SimpleTransmission</type>
    <joint name="leg1joint5">
      <hardwareInterface>EffortJointInterface</hardwareInterface>
    </joint>
    <actuator name="motor5">
      <hardwareInterface>EffortJointInterface</hardwareInterface>
      <mechanicalReduction>1</mechanicalReduction>
    </actuator>
  </transmission>
  <!-- Link0 -->
  <gazebo reference="leg2link0">
    <mu1>0.2</mu1>
    <mu2>0.2</mu2>
    <material>Gazebo/Black</material>
  </gazebo>
  <!-- Link1 -->
  <gazebo reference="leg2link1">
    <material>Gazebo/Orange</material>
  </gazebo>
  <!-- Link2 -->
  <gazebo reference="leg2link2">
    <mu1>0.2</mu1>
    <mu2>0.2</mu2>
    <material>Gazebo/Black</material>
  </gazebo>
  <!-- Link3 -->
  <gazebo reference="leg2link3">
    <mu1>0.2</mu1>
    <mu2>0.2</mu2>
    <material>Gazebo/Orange</material>
  </gazebo>
  <!-- Link4 -->
  <gazebo reference="leg2link4">
    <mu1>0.2</mu1>
    <mu2>0.2</mu2>
    <material>Gazebo/Black</material>
  </gazebo>
  <!-- Link5 -->
  <gazebo reference="leg2link5">
    <mu1>0.2</mu1>
    <mu2>0.2</mu2>
    <material>Gazebo/Orange</material>
  </gazebo>
  <link name="leg2link0">
    <self_collide>1</self_collide>
    <inertial>
      <origin rpy="0 0 0" xyz="0 0 0"/>
      <mass value="0.47264202"/>
      <inertia ixx="4.39200522187e-05" ixy="0" ixz="0" iyy="5.31290419486e-05" iyz="0" izz="5.01277802462e-05"/>
    </inertial>
    <collision name="collision">
      <origin rpy="0 0 0" xyz="0 0 0"/>
      <geometry>
        <mesh filename="package://daedalus_description/meshes/link0.dae"/>
      </geometry>
    </collision>
    <visual name="visual">
      <origin rpy="0 0 0" xyz="0 0 0"/>
      <geometry>
        <mesh filename="package://daedalus_description/meshes/link0.dae"/>
      </geometry>
    </visual>
  </link>
  <link name="leg2link1">
    <self_collide>1</self_collide>
    <inertial>
      <origin rpy="0 0 0" xyz="-0.0236 0 0"/>
      <mass value="0.62343552"/>
      <inertia ixx="0.000160071617099" ixy="2.87852024859e-07" ixz="2.50811887715e-05" iyy="0.000174781160491" iyz="-1.05497821038e-06" izz="7.16466070774e-05"/>
    </inertial>
    <collision name="collision">
      <origin rpy="0 0 0" xyz="-0.0236 0 0"/>
      <geometry>
        <mesh filename="package://daedalus_description/meshes/link1.dae"/>
      </geometry>
    </collision>
    <visual name="visual">
      <origin rpy="0 0 0" xyz="-0.0236 0 0"/>
      <geometry>
        <mesh filename="package://daedalus_description/meshes/link1.dae"/>
      </geometry>
    </visual>
  </link>
  <link name="leg2link2">
    <self_collide>1</self_collide>
    <inertial>
      <origin rpy="0 0 0" xyz="0 0.0371 -0.0015"/>
      <mass value="0.73212067"/>
      <inertia ixx="0.000225692997965" ixy="0" ixz="0" iyy="0.00010348394328" iyz="-4.53711798338e-06" izz="0.000234791733618"/>
    </inertial>
    <collision name="collision">
      <origin rpy="0 0 0" xyz="0 0.0371 -0.0015"/>
      <geometry>
        <mesh filename="package://daedalus_description/meshes/link2.dae"/>
      </geometry>
    </collision>
    <visual name="visual">
      <origin rpy="0 0 0" xyz="0 0.0371 -0.0015"/>
      <geometry>
        <mesh filename="package://daedalus_description/meshes/link2.dae"/>
      </geometry>
    </visual>
  </link>
  <link name="leg2link3">
    <self_collide>1</self_collide>
    <inertial>
      <origin rpy="0 0 0" xyz=" 0 -0.0041 -0.0371"/>
      <mass value="0.43109013"/>
      <inertia ixx="7.65993537709e-05" ixy="0" ixz="0" iyy="8.9932317097e-05" iyz="-6.34504749832e-06" izz="2.57010322713e-05"/>
    </inertial>
    <collision name="collision">
      <origin rpy="0 0 0" xyz="0 -0.0041 -0.0371"/>
      <geometry>
        <mesh filename="package://daedalus_description/meshes/link3.dae"/>
      </geometry>
    </collision>
    <visual name="visual">
      <origin rpy="0 0 0" xyz="0 -0.0041 -0.0371"/>
      <geometry>
        <mesh filename="package://daedalus_description/meshes/link3.dae"/>
      </geometry>
    </visual>
  </link>
  <link name="leg2link4">
    <self_collide>1</self_collide>
    <inertial>
      <origin rpy="0 0 0" xyz="0.0002  -0.0233 -0.0124"/>
      <mass value="0.79043472"/>
      <inertia ixx="0.000481530525726" ixy="1.06797010376e-05" ixz="-4.12651188184e-06" iyy="0.000185315488282" iyz="0.000142151873316" izz="0.000404192441138"/>
    </inertial>
    <collision name="collision">
      <origin rpy="0 0 0" xyz="0.0002  -0.0233 -0.0124"/>
      <geometry>
        <mesh filename="package://daedalus_description/meshes/link4.dae"/>
      </geometry>
    </collision>
    <visual name="visual">
      <origin rpy="0 0 0" xyz="0.0002  -0.0233 -0.0124"/>
      <geometry>
        <mesh filename="package://daedalus_description/meshes/link4.dae"/>
      </geometry>
    </visual>
  </link>
  <link name="leg2link5">
    <self_collide>1</self_collide>
    <inertial>
      <origin rpy="0 0 0" xyz="-0.0006 -0.0009 -0.0311"/>
      <mass value="0.65552696"/>
      <inertia ixx="0.000252796206096" ixy="-1.46765275547e-07" ixz="-8.81848495125e-06" iyy="0.000187690504097" iyz="-2.34414867631e-06" izz="0.000221889194174"/>
    </inertial>
    <collision name="collision">
      <surface>
        <friction>
          <ode>
            <mu>100</mu>
            <mu2>10</mu2>
          </ode>
        </friction>
      </surface>
      <origin rpy="0 0 0" xyz="-0.0006 -0.0009 -0.0311"/>
      <geometry>
        <mesh filename="package://daedalus_description/meshes/link5.dae"/>
      </geometry>
    </collision>
    <visual name="visual">
      <origin rpy="0 0 0" xyz="-0.0006 -0.0009 -0.0311"/>
      <geometry>
        <mesh filename="package://daedalus_description/meshes/link5.dae"/>
      </geometry>
    </visual>
  </link>
  <!-- -->
  <joint name="leg2joint0" type="fixed">
    <child link="leg2link0"/>
    <parent link="frame"/>
    <origin rpy="0 0 3.14" xyz="0.14 -0.0625 0"/>
    <axis xyz="1 0 0"/>
  </joint>
  <joint name="leg2joint1" type="revolute">
    <origin rpy="0 0 0" xyz="-0.0249 0 0.0205"/>
    <child link="leg2link1"/>
    <parent link="leg2link0"/>
    &quot;
      
    <axis xyz="0 0 -1"/>
    <limit effort="100" lower="-1.57" upper="1.57" velocity="10"/>
  </joint>
  <joint name="leg2joint2" type="revolute">
    <origin rpy="1.570795 0 0.0" xyz="-0.0309 0.0002 0.0381"/>
    <child link="leg2link2"/>
    <parent link="leg2link1"/>
    <axis xyz="1.0 0 0"/>
    <limit effort="100" lower="-1.57" upper="1.57" velocity="10"/>
  </joint>
  <joint name="leg2joint3" type="revolute">
    <origin rpy="0 0 0" xyz="0 0.0564 -0.0208"/>
    <child link="leg2link3"/>
    <parent link="leg2link2"/>
    <axis xyz="-1.0 0 0"/>
    <limit effort="100" lower="-1.57" upper="1.57" velocity="10"/>
  </joint>
  <joint name="leg2joint4" type="revolute">
    <origin rpy="-0.7853975 0 0" xyz="0 -0.0171 -0.0742"/>
    <child link="leg2link4"/>
    <parent link="leg2link3"/>
    <axis xyz="-1.0 0 0"/>
    <limit effort="100" lower="-1.57" upper="1.57" velocity="10"/>
  </joint>
  <joint name="leg2joint5" type="revolute">
    <origin rpy="0 0 0" xyz="-0.0004 -0.0411 -0.0248"/>
    <child link="leg2link5"/>
    <parent link="leg2link4"/>
    <axis xyz="0 1 0"/>
    <limit effort="100" lower="-1.57" upper="1.57" velocity="10"/>
  </joint>
  <!-- -->
  <transmission name="tran1">
    <type>transmission_interface/SimpleTransmission</type>
    <joint name="leg2joint1">
      <hardwareInterface>EffortJointInterface</hardwareInterface>
    </joint>
    <actuator name="motor1">
      <hardwareInterface>EffortJointInterface</hardwareInterface>
      <mechanicalReduction>1</mechanicalReduction>
    </actuator>
  </transmission>
  <transmission name="tran2">
    <type>transmission_interface/SimpleTransmission</type>
    <joint name="leg2joint2">
      <hardwareInterface>EffortJointInterface</hardwareInterface>
    </joint>
    <actuator name="motor2">
      <hardwareInterface>EffortJointInterface</hardwareInterface>
      <mechanicalReduction>1</mechanicalReduction>
    </actuator>
  </transmission>
  <transmission name="tran3">
    <type>transmission_interface/SimpleTransmission</type>
    <joint name="leg2joint3">
      <hardwareInterface>EffortJointInterface</hardwareInterface>
    </joint>
    <actuator name="motor3">
      <hardwareInterface>EffortJointInterface</hardwareInterface>
      <mechanicalReduction>1</mechanicalReduction>
    </actuator>
  </transmission>
  <transmission name="tran4">
    <type>transmission_interface/SimpleTransmission</type>
    <joint name="leg2joint4">
      <hardwareInterface>EffortJointInterface</hardwareInterface>
    </joint>
    <actuator name="motor4">
      <hardwareInterface>EffortJointInterface</hardwareInterface>
      <mechanicalReduction>1</mechanicalReduction>
    </actuator>
  </transmission>
  <transmission name="tran5">
    <type>transmission_interface/SimpleTransmission</type>
    <joint name="leg2joint5">
      <hardwareInterface>EffortJointInterface</hardwareInterface>
    </joint>
    <actuator name="motor5">
      <hardwareInterface>EffortJointInterface</hardwareInterface>
      <mechanicalReduction>1</mechanicalReduction>
    </actuator>
  </transmission>
  <!-- Link0 -->
  <gazebo reference="leg3link0">
    <mu1>0.2</mu1>
    <mu2>0.2</mu2>
    <material>Gazebo/Black</material>
  </gazebo>
  <!-- Link1 -->
  <gazebo reference="leg3link1">
    <material>Gazebo/Orange</material>
  </gazebo>
  <!-- Link2 -->
  <gazebo reference="leg3link2">
    <mu1>0.2</mu1>
    <mu2>0.2</mu2>
    <material>Gazebo/Black</material>
  </gazebo>
  <!-- Link3 -->
  <gazebo reference="leg3link3">
    <mu1>0.2</mu1>
    <mu2>0.2</mu2>
    <material>Gazebo/Orange</material>
  </gazebo>
  <!-- Link4 -->
  <gazebo reference="leg3link4">
    <mu1>0.2</mu1>
    <mu2>0.2</mu2>
    <material>Gazebo/Black</material>
  </gazebo>
  <!-- Link5 -->
  <gazebo reference="leg3link5">
    <mu1>0.2</mu1>
    <mu2>0.2</mu2>
    <material>Gazebo/Orange</material>
  </gazebo>
  <link name="leg3link0">
    <self_collide>1</self_collide>
    <inertial>
      <origin rpy="0 0 0" xyz="0 0 0"/>
      <mass value="0.47264202"/>
      <inertia ixx="4.39200522187e-05" ixy="0" ixz="0" iyy="5.31290419486e-05" iyz="0" izz="5.01277802462e-05"/>
    </inertial>
    <collision name="collision">
      <origin rpy="0 0 0" xyz="0 0 0"/>
      <geometry>
        <mesh filename="package://daedalus_description/meshes/link0.dae"/>
      </geometry>
    </collision>
    <visual name="visual">
      <origin rpy="0 0 0" xyz="0 0 0"/>
      <geometry>
        <mesh filename="package://daedalus_description/meshes/link0.dae"/>
      </geometry>
    </visual>
  </link>
  <link name="leg3link1">
    <self_collide>1</self_collide>
    <inertial>
      <origin rpy="0 0 0" xyz="-0.0236 0 0"/>
      <mass value="0.62343552"/>
      <inertia ixx="0.000160071617099" ixy="2.87852024859e-07" ixz="2.50811887715e-05" iyy="0.000174781160491" iyz="-1.05497821038e-06" izz="7.16466070774e-05"/>
    </inertial>
    <collision name="collision">
      <origin rpy="0 0 0" xyz="-0.0236 0 0"/>
      <geometry>
        <mesh filename="package://daedalus_description/meshes/link1.dae"/>
      </geometry>
    </collision>
    <visual name="visual">
      <origin rpy="0 0 0" xyz="-0.0236 0 0"/>
      <geometry>
        <mesh filename="package://daedalus_description/meshes/link1.dae"/>
      </geometry>
    </visual>
  </link>
  <link name="leg3link2">
    <self_collide>1</self_collide>
    <inertial>
      <origin rpy="0 0 0" xyz="0 0.0371 -0.0015"/>
      <mass value="0.73212067"/>
      <inertia ixx="0.000225692997965" ixy="0" ixz="0" iyy="0.00010348394328" iyz="-4.53711798338e-06" izz="0.000234791733618"/>
    </inertial>
    <collision name="collision">
      <origin rpy="0 0 0" xyz="0 0.0371 -0.0015"/>
      <geometry>
        <mesh filename="package://daedalus_description/meshes/link2.dae"/>
      </geometry>
    </collision>
    <visual name="visual">
      <origin rpy="0 0 0" xyz="0 0.0371 -0.0015"/>
      <geometry>
        <mesh filename="package://daedalus_description/meshes/link2.dae"/>
      </geometry>
    </visual>
  </link>
  <link name="leg3link3">
    <self_collide>1</self_collide>
    <inertial>
      <origin rpy="0 0 0" xyz=" 0 -0.0041 -0.0371"/>
      <mass value="0.43109013"/>
      <inertia ixx="7.65993537709e-05" ixy="0" ixz="0" iyy="8.9932317097e-05" iyz="-6.34504749832e-06" izz="2.57010322713e-05"/>
    </inertial>
    <collision name="collision">
      <origin rpy="0 0 0" xyz="0 -0.0041 -0.0371"/>
      <geometry>
        <mesh filename="package://daedalus_description/meshes/link3.dae"/>
      </geometry>
    </collision>
    <visual name="visual">
      <origin rpy="0 0 0" xyz="0 -0.0041 -0.0371"/>
      <geometry>
        <mesh filename="package://daedalus_description/meshes/link3.dae"/>
      </geometry>
    </visual>
  </link>
  <link name="leg3link4">
    <self_collide>1</self_collide>
    <inertial>
      <origin rpy="0 0 0" xyz="0.0002  -0.0233 -0.0124"/>
      <mass value="0.79043472"/>
      <inertia ixx="0.000481530525726" ixy="1.06797010376e-05" ixz="-4.12651188184e-06" iyy="0.000185315488282" iyz="0.000142151873316" izz="0.000404192441138"/>
    </inertial>
    <collision name="collision">
      <origin rpy="0 0 0" xyz="0.0002  -0.0233 -0.0124"/>
      <geometry>
        <mesh filename="package://daedalus_description/meshes/link4.dae"/>
      </geometry>
    </collision>
    <visual name="visual">
      <origin rpy="0 0 0" xyz="0.0002  -0.0233 -0.0124"/>
      <geometry>
        <mesh filename="package://daedalus_description/meshes/link4.dae"/>
      </geometry>
    </visual>
  </link>
  <link name="leg3link5">
    <self_collide>1</self_collide>
    <inertial>
      <origin rpy="0 0 0" xyz="-0.0006 -0.0009 -0.0311"/>
      <mass value="0.65552696"/>
      <inertia ixx="0.000252796206096" ixy="-1.46765275547e-07" ixz="-8.81848495125e-06" iyy="0.000187690504097" iyz="-2.34414867631e-06" izz="0.000221889194174"/>
    </inertial>
    <collision name="collision">
      <surface>
        <friction>
          <ode>
            <mu>100</mu>
            <mu2>10</mu2>
          </ode>
        </friction>
      </surface>
      <origin rpy="0 0 0" xyz="-0.0006 -0.0009 -0.0311"/>
      <geometry>
        <mesh filename="package://daedalus_description/meshes/link5.dae"/>
      </geometry>
    </collision>
    <visual name="visual">
      <origin rpy="0 0 0" xyz="-0.0006 -0.0009 -0.0311"/>
      <geometry>
        <mesh filename="package://daedalus_description/meshes/link5.dae"/>
      </geometry>
    </visual>
  </link>
  <!-- -->
  <joint name="leg3joint0" type="fixed">
    <child link="leg3link0"/>
    <parent link="frame"/>
    <origin rpy="0 0 0" xyz="-0.14 0.0625 0"/>
    <axis xyz="1 0 0"/>
  </joint>
  <joint name="leg3joint1" type="revolute">
    <origin rpy="0 0 0" xyz="-0.0249 0 0.0205"/>
    <child link="leg3link1"/>
    <parent link="leg3link0"/>
    &quot;
      
    <axis xyz="0 0 -1"/>
    <limit effort="100" lower="-1.57" upper="1.57" velocity="10"/>
  </joint>
  <joint name="leg3joint2" type="revolute">
    <origin rpy="1.570795 0 0.0" xyz="-0.0309 0.0002 0.0381"/>
    <child link="leg3link2"/>
    <parent link="leg3link1"/>
    <axis xyz="1.0 0 0"/>
    <limit effort="100" lower="-1.57" upper="1.57" velocity="10"/>
  </joint>
  <joint name="leg3joint3" type="revolute">
    <origin rpy="0 0 0" xyz="0 0.0564 -0.0208"/>
    <child link="leg3link3"/>
    <parent link="leg3link2"/>
    <axis xyz="-1.0 0 0"/>
    <limit effort="100" lower="-1.57" upper="1.57" velocity="10"/>
  </joint>
  <joint name="leg3joint4" type="revolute">
    <origin rpy="-0.7853975 0 0" xyz="0 -0.0171 -0.0742"/>
    <child link="leg3link4"/>
    <parent link="leg3link3"/>
    <axis xyz="-1.0 0 0"/>
    <limit effort="100" lower="-1.57" upper="1.57" velocity="10"/>
  </joint>
  <joint name="leg3joint5" type="revolute">
    <origin rpy="0 0 0" xyz="-0.0004 -0.0411 -0.0248"/>
    <child link="leg3link5"/>
    <parent link="leg3link4"/>
    <axis xyz="0 1 0"/>
    <limit effort="100" lower="-1.57" upper="1.57" velocity="10"/>
  </joint>
  <!-- -->
  <transmission name="tran1">
    <type>transmission_interface/SimpleTransmission</type>
    <joint name="leg3joint1">
      <hardwareInterface>EffortJointInterface</hardwareInterface>
    </joint>
    <actuator name="motor1">
      <hardwareInterface>EffortJointInterface</hardwareInterface>
      <mechanicalReduction>1</mechanicalReduction>
    </actuator>
  </transmission>
  <transmission name="tran2">
    <type>transmission_interface/SimpleTransmission</type>
    <joint name="leg3joint2">
      <hardwareInterface>EffortJointInterface</hardwareInterface>
    </joint>
    <actuator name="motor2">
      <hardwareInterface>EffortJointInterface</hardwareInterface>
      <mechanicalReduction>1</mechanicalReduction>
    </actuator>
  </transmission>
  <transmission name="tran3">
    <type>transmission_interface/SimpleTransmission</type>
    <joint name="leg3joint3">
      <hardwareInterface>EffortJointInterface</hardwareInterface>
    </joint>
    <actuator name="motor3">
      <hardwareInterface>EffortJointInterface</hardwareInterface>
      <mechanicalReduction>1</mechanicalReduction>
    </actuator>
  </transmission>
  <transmission name="tran4">
    <type>transmission_interface/SimpleTransmission</type>
    <joint name="leg3joint4">
      <hardwareInterface>EffortJointInterface</hardwareInterface>
    </joint>
    <actuator name="motor4">
      <hardwareInterface>EffortJointInterface</hardwareInterface>
      <mechanicalReduction>1</mechanicalReduction>
    </actuator>
  </transmission>
  <transmission name="tran5">
    <type>transmission_interface/SimpleTransmission</type>
    <joint name="leg3joint5">
      <hardwareInterface>EffortJointInterface</hardwareInterface>
    </joint>
    <actuator name="motor5">
      <hardwareInterface>EffortJointInterface</hardwareInterface>
      <mechanicalReduction>1</mechanicalReduction>
    </actuator>
  </transmission>
  <!-- Link0 -->
  <gazebo reference="leg4link0">
    <mu1>0.2</mu1>
    <mu2>0.2</mu2>
    <material>Gazebo/Black</material>
  </gazebo>
  <!-- Link1 -->
  <gazebo reference="leg4link1">
    <material>Gazebo/Orange</material>
  </gazebo>
  <!-- Link2 -->
  <gazebo reference="leg4link2">
    <mu1>0.2</mu1>
    <mu2>0.2</mu2>
    <material>Gazebo/Black</material>
  </gazebo>
  <!-- Link3 -->
  <gazebo reference="leg4link3">
    <mu1>0.2</mu1>
    <mu2>0.2</mu2>
    <material>Gazebo/Orange</material>
  </gazebo>
  <!-- Link4 -->
  <gazebo reference="leg4link4">
    <mu1>0.2</mu1>
    <mu2>0.2</mu2>
    <material>Gazebo/Black</material>
  </gazebo>
  <!-- Link5 -->
  <gazebo reference="leg4link5">
    <mu1>0.2</mu1>
    <mu2>0.2</mu2>
    <material>Gazebo/Orange</material>
  </gazebo>
  <link name="leg4link0">
    <self_collide>1</self_collide>
    <inertial>
      <origin rpy="0 0 0" xyz="0 0 0"/>
      <mass value="0.47264202"/>
      <inertia ixx="4.39200522187e-05" ixy="0" ixz="0" iyy="5.31290419486e-05" iyz="0" izz="5.01277802462e-05"/>
    </inertial>
    <collision name="collision">
      <origin rpy="0 0 0" xyz="0 0 0"/>
      <geometry>
        <mesh filename="package://daedalus_description/meshes/link0.dae"/>
      </geometry>
    </collision>
    <visual name="visual">
      <origin rpy="0 0 0" xyz="0 0 0"/>
      <geometry>
        <mesh filename="package://daedalus_description/meshes/link0.dae"/>
      </geometry>
    </visual>
  </link>
  <link name="leg4link1">
    <self_collide>1</self_collide>
    <inertial>
      <origin rpy="0 0 0" xyz="-0.0236 0 0"/>
      <mass value="0.62343552"/>
      <inertia ixx="0.000160071617099" ixy="2.87852024859e-07" ixz="2.50811887715e-05" iyy="0.000174781160491" iyz="-1.05497821038e-06" izz="7.16466070774e-05"/>
    </inertial>
    <collision name="collision">
      <origin rpy="0 0 0" xyz="-0.0236 0 0"/>
      <geometry>
        <mesh filename="package://daedalus_description/meshes/link1.dae"/>
      </geometry>
    </collision>
    <visual name="visual">
      <origin rpy="0 0 0" xyz="-0.0236 0 0"/>
      <geometry>
        <mesh filename="package://daedalus_description/meshes/link1.dae"/>
      </geometry>
    </visual>
  </link>
  <link name="leg4link2">
    <self_collide>1</self_collide>
    <inertial>
      <origin rpy="0 0 0" xyz="0 0.0371 -0.0015"/>
      <mass value="0.73212067"/>
      <inertia ixx="0.000225692997965" ixy="0" ixz="0" iyy="0.00010348394328" iyz="-4.53711798338e-06" izz="0.000234791733618"/>
    </inertial>
    <collision name="collision">
      <origin rpy="0 0 0" xyz="0 0.0371 -0.0015"/>
      <geometry>
        <mesh filename="package://daedalus_description/meshes/link2.dae"/>
      </geometry>
    </collision>
    <visual name="visual">
      <origin rpy="0 0 0" xyz="0 0.0371 -0.0015"/>
      <geometry>
        <mesh filename="package://daedalus_description/meshes/link2.dae"/>
      </geometry>
    </visual>
  </link>
  <link name="leg4link3">
    <self_collide>1</self_collide>
    <inertial>
      <origin rpy="0 0 0" xyz=" 0 -0.0041 -0.0371"/>
      <mass value="0.43109013"/>
      <inertia ixx="7.65993537709e-05" ixy="0" ixz="0" iyy="8.9932317097e-05" iyz="-6.34504749832e-06" izz="2.57010322713e-05"/>
    </inertial>
    <collision name="collision">
      <origin rpy="0 0 0" xyz="0 -0.0041 -0.0371"/>
      <geometry>
        <mesh filename="package://daedalus_description/meshes/link3.dae"/>
      </geometry>
    </collision>
    <visual name="visual">
      <origin rpy="0 0 0" xyz="0 -0.0041 -0.0371"/>
      <geometry>
        <mesh filename="package://daedalus_description/meshes/link3.dae"/>
      </geometry>
    </visual>
  </link>
  <link name="leg4link4">
    <self_collide>1</self_collide>
    <inertial>
      <origin rpy="0 0 0" xyz="0.0002  -0.0233 -0.0124"/>
      <mass value="0.79043472"/>
      <inertia ixx="0.000481530525726" ixy="1.06797010376e-05" ixz="-4.12651188184e-06" iyy="0.000185315488282" iyz="0.000142151873316" izz="0.000404192441138"/>
    </inertial>
    <collision name="collision">
      <origin rpy="0 0 0" xyz="0.0002  -0.0233 -0.0124"/>
      <geometry>
        <mesh filename="package://daedalus_description/meshes/link4.dae"/>
      </geometry>
    </collision>
    <visual name="visual">
      <origin rpy="0 0 0" xyz="0.0002  -0.0233 -0.0124"/>
      <geometry>
        <mesh filename="package://daedalus_description/meshes/link4.dae"/>
      </geometry>
    </visual>
  </link>
  <link name="leg4link5">
    <self_collide>1</self_collide>
    <inertial>
      <origin rpy="0 0 0" xyz="-0.0006 -0.0009 -0.0311"/>
      <mass value="0.65552696"/>
      <inertia ixx="0.000252796206096" ixy="-1.46765275547e-07" ixz="-8.81848495125e-06" iyy="0.000187690504097" iyz="-2.34414867631e-06" izz="0.000221889194174"/>
    </inertial>
    <collision name="collision">
      <surface>
        <friction>
          <ode>
            <mu>100</mu>
            <mu2>10</mu2>
          </ode>
        </friction>
      </surface>
      <origin rpy="0 0 0" xyz="-0.0006 -0.0009 -0.0311"/>
      <geometry>
        <mesh filename="package://daedalus_description/meshes/link5.dae"/>
      </geometry>
    </collision>
    <visual name="visual">
      <origin rpy="0 0 0" xyz="-0.0006 -0.0009 -0.0311"/>
      <geometry>
        <mesh filename="package://daedalus_description/meshes/link5.dae"/>
      </geometry>
    </visual>
  </link>
  <!-- -->
  <joint name="leg4joint0" type="fixed">
    <child link="leg4link0"/>
    <parent link="frame"/>
    <origin rpy="0 0 0" xyz="-0.14 -0.0625 0"/>
    <axis xyz="1 0 0"/>
  </joint>
  <joint name="leg4joint1" type="revolute">
    <origin rpy="0 0 0" xyz="-0.0249 0 0.0205"/>
    <child link="leg4link1"/>
    <parent link="leg4link0"/>
    &quot;
      
    <axis xyz="0 0 -1"/>
    <limit effort="100" lower="-1.57" upper="1.57" velocity="10"/>
  </joint>
  <joint name="leg4joint2" type="revolute">
    <origin rpy="1.570795 0 3.14159" xyz="-0.0309 0.0002 0.0381"/>
    <child link="leg4link2"/>
    <parent link="leg4link1"/>
    <axis xyz="-1.0 0 0"/>
    <limit effort="100" lower="-1.57" upper="1.57" velocity="10"/>
  </joint>
  <joint name="leg4joint3" type="revolute">
    <origin rpy="0 0 0" xyz="0 0.0564 -0.0208"/>
    <child link="leg4link3"/>
    <parent link="leg4link2"/>
    <axis xyz="1.0 0 0"/>
    <limit effort="100" lower="-1.57" upper="1.57" velocity="10"/>
  </joint>
  <joint name="leg4joint4" type="revolute">
    <origin rpy="-0.7853975 0 0" xyz="0 -0.0171 -0.0742"/>
    <child link="leg4link4"/>
    <parent link="leg4link3"/>
    <axis xyz="1.0 0 0"/>
    <limit effort="100" lower="-1.57" upper="1.57" velocity="10"/>
  </joint>
  <joint name="leg4joint5" type="revolute">
    <origin rpy="0 0 0" xyz="-0.0004 -0.0411 -0.0248"/>
    <child link="leg4link5"/>
    <parent link="leg4link4"/>
    <axis xyz="0 1 0"/>
    <limit effort="100" lower="-1.57" upper="1.57" velocity="10"/>
  </joint>
  <!-- -->
  <transmission name="tran1">
    <type>transmission_interface/SimpleTransmission</type>
    <joint name="leg4joint1">
      <hardwareInterface>EffortJointInterface</hardwareInterface>
    </joint>
    <actuator name="motor1">
      <hardwareInterface>EffortJointInterface</hardwareInterface>
      <mechanicalReduction>1</mechanicalReduction>
    </actuator>
  </transmission>
  <transmission name="tran2">
    <type>transmission_interface/SimpleTransmission</type>
    <joint name="leg4joint2">
      <hardwareInterface>EffortJointInterface</hardwareInterface>
    </joint>
    <actuator name="motor2">
      <hardwareInterface>EffortJointInterface</hardwareInterface>
      <mechanicalReduction>1</mechanicalReduction>
    </actuator>
  </transmission>
  <transmission name="tran3">
    <type>transmission_interface/SimpleTransmission</type>
    <joint name="leg4joint3">
      <hardwareInterface>EffortJointInterface</hardwareInterface>
    </joint>
    <actuator name="motor3">
      <hardwareInterface>EffortJointInterface</hardwareInterface>
      <mechanicalReduction>1</mechanicalReduction>
    </actuator>
  </transmission>
  <transmission name="tran4">
    <type>transmission_interface/SimpleTransmission</type>
    <joint name="leg4joint4">
      <hardwareInterface>EffortJointInterface</hardwareInterface>
    </joint>
    <actuator name="motor4">
      <hardwareInterface>EffortJointInterface</hardwareInterface>
      <mechanicalReduction>1</mechanicalReduction>
    </actuator>
  </transmission>
  <transmission name="tran5">
    <type>transmission_interface/SimpleTransmission</type>
    <joint name="leg4joint5">
      <hardwareInterface>EffortJointInterface</hardwareInterface>
    </joint>
    <actuator name="motor5">
      <hardwareInterface>EffortJointInterface</hardwareInterface>
      <mechanicalReduction>1</mechanicalReduction>
    </actuator>
  </transmission>
</robot>
