<?xml version="1.0"?>

<robot xmlns:xacro="http://www.ros.org/wiki/xacro">
	<macro name="leg" params="suffix parent *origin">
	
    
    <link name="leg${suffix}link0">
      <inertial>
        <origin xyz="0 0 0" rpy="0 0 0"/>
          <mass value="${4.72639954 * const}"/>
        <inertia ixx="3.76702192" ixy="0" ixz="0" iyy="5.02939053" iyz="0" izz="0.104767786"/>
      </inertial>
      <collision name="collision">
        <origin xyz="0 0 0" rpy="0 0 0"/>
        <geometry>
          <mesh filename="package://daedalus_description/meshes/link0.dae"/>
        </geometry>
      </collision>
      <visual name="visual">
        <origin xyz="0 0 0" rpy="0 0 0"/>
        <geometry>
          <mesh filename="package://daedalus_description/meshes/link0.dae"/>
        </geometry>
      </visual>
    </link>
    <link name="leg${suffix}link1">
      <inertial>
        <origin xyz="0.837170246 1.0317214 0.161524277" rpy="0 0 0"/>
        <mass value="${6.23121787 * const}"/>
        <inertia ixx="4.36786663" ixy="0" ixz="0" iyy="6.63326988" iyz="0" izz="0.164683289"/>
      </inertial>
      <collision name="collision">
        <origin xyz="-0.86 -1.03 -0.17" rpy="0 0 0"/>
        <geometry>
          <mesh filename="package://daedalus_description/meshes/link1.dae"/>
        </geometry>
      </collision>
      <visual name="visual">
        <origin xyz="-0.86 -1.03 -0.17" rpy="0 0 0"/>
        <geometry>
          <mesh filename="package://daedalus_description/meshes/link1.dae"/>
        </geometry>
      </visual>
    </link> 
    <link name="leg${suffix}link2">
      <self_collide>1</self_collide>
      <inertial>
        <origin xyz="-0.017799314 0.04493617  -0.002242117" rpy="0 0 0"/>
        <mass value="${7.32147232 * const}"/>
        <inertia ixx="5.071313" ixy="0" ixz="0" iyy="8.46231008" iyz="0" izz="0.316663829"/>
      </inertial>
      <collision name="collision">
        <origin xyz="-0.85 -1.03 -0.21" rpy="0 0 0"/>
        <geometry>
          <mesh filename="package://daedalus_description/meshes/link2.dae"/>
        </geometry>
      </collision>
      <visual name="visual">
        <origin xyz="-0.85 -1.03 -0.21" rpy="0 0 0"/>
        <geometry>
          <mesh filename="package://daedalus_description/meshes/link2.dae"/>
        </geometry>
      </visual>
    </link>
    <link name="leg${suffix}link3">
      <self_collide>1</self_collide>
      <inertial>
        <origin xyz=" -0.0177993  -0.0027828  -0.0402923" rpy="0 0 0"/>
        <mass value="${4.31132052  * const}"/>
        <inertia ixx="2.98629222" ixy="0" ixz="0" iyy="5.09630234" iyz="0" izz="0.0982604921"/>
      </inertial>
      <collision name="collision">
        <origin xyz="-0.85 -1.09 -0.19" rpy="0 0 0"/>
        <geometry>
          <mesh filename="package://daedalus_description/meshes/link3.dae"/>
        </geometry>
      </collision>
      <visual name="visual">
        <origin xyz="-0.85 -1.09 -0.19" rpy="0 0 0"/>
        <geometry>
          <mesh filename="package://daedalus_description/meshes/link3.dae"/>
        </geometry>
      </visual>
    </link>
    <link name="leg${suffix}link4">
      <self_collide>1</self_collide>
      <inertial>
        <origin xyz="0.0230260  -0.0192363  -0.0096265" rpy="0 0 0"/>
        <mass value="${7.90197358 * const}"/>
        <inertia ixx="5.48411837" ixy="0" ixz="0" iyy="8.72903423" iyz="0" izz="0.0812723132"/>
      </inertial>
      <collision name="collision">
        <origin xyz="-0.81 -1.07 -0.11" rpy="0 0 0"/>
        <geometry>
          <mesh filename="package://daedalus_description/meshes/link4.dae"/>
        </geometry>
      </collision>
      <visual name="visual">
        <origin xyz="-0.81 -1.07 -0.11" rpy="0 0 0"/>
        <geometry>
          <mesh filename="package://daedalus_description/meshes/link4.dae"/>
        </geometry>
      </visual>
    </link>
    <link name="leg${suffix}link5">
      <self_collide>1</self_collide>
      <inertial>
        <origin xyz="0.0019165   0.0104236  -0.0496145" rpy="0 0 0"/>
        <mass value="${6.55679875 * const}"/>
        <inertia ixx="4.53905844" ixy="0" ixz="0" iyy="7.09980012" iyz="0" izz="0.012361989"/>
      </inertial>
      <collision name="collision">
        <origin xyz="-0.83 -1.03 -0.09" rpy="0 0 0"/>
        <geometry>
          <mesh filename="package://daedalus_description/meshes/link5.dae"/>
        </geometry>
      </collision>
      <visual name="visual">
        <origin xyz="-0.83 -1.03 -0.09" rpy="0 0 0"/>
        <geometry>
          <mesh filename="package://daedalus_description/meshes/link5.dae"/>
        </geometry>
      </visual>
    </link>
    
    
    <joint type="fixed" name="leg${suffix}joint0">
      
      <child link="leg${suffix}link0"/>
      <parent link="${parent}"/>
      <insert_block name="origin" />
      <axis xyz="1 0 0"/>
    </joint>
    <joint type="revolute" name="leg${suffix}joint1">
      <origin xyz="0 0 0" rpy="0 0 0"/>
      <child link="leg${suffix}link1"/>
      <parent link="leg${suffix}link0"/>"
      <axis xyz="0 0 1"/>
      <limit lower="-1.57" upper="1.57" effort="100" velocity="0.5"/>
    </joint>
    <joint type="revolute" name="leg${suffix}joint2">
      <origin xyz="-0.01 0 0.04" rpy="0 0 0"/>
      <child link="leg${suffix}link2"/>
      <parent link="leg${suffix}link1"/>
      <axis xyz="1 0 0"/>
      <limit lower="-0.45" upper="3.59" effort="100" velocity="0.5"/>
    </joint>
    <joint type="revolute" name="leg${suffix}joint3">
      <origin xyz="0 0.06 -0.02" rpy="0 0 0"/>
      <child link="leg${suffix}link3"/>
      <parent link="leg${suffix}link2"/>
      <axis xyz="1 0 0"/>
      <limit lower="-1.57" upper="1.57" effort="100" velocity="0.5"/>
    </joint>
    <joint type="revolute" name="leg${suffix}joint4">
      <origin xyz="-0.04 -0.02 -0.08" rpy="0 0 0"/>
      <child link="leg${suffix}link4"/>
      <parent link="leg${suffix}link3"/>
      <axis xyz="1 0 0"/>
      <limit lower="-1.57" upper="1.57" effort="100" velocity="0.5"/>
    </joint>
    <joint type="revolute" name="leg${suffix}joint5">
      <origin xyz="0.02 -0.04 -0.02" rpy="0 0 0"/>
      <child link="leg${suffix}link5"/>
      <parent link="leg${suffix}link4"/>
      <axis xyz="0 1 0"/>
      <limit lower="-1.57" upper="1.57" effort="100" velocity="0.5"/>
    </joint>
    
<transmission name="tran1">
    <type>transmission_interface/SimpleTransmission</type>
    <joint name="leg${suffix}joint1">
	      <hardwareInterface>EffortJointInterface</hardwareInterface>
    </joint>
    <actuator name="motor1">
      <hardwareInterface>EffortJointInterface</hardwareInterface>
      <mechanicalReduction>1</mechanicalReduction>
    </actuator>
  </transmission>
  <transmission name="tran2">
    <type>transmission_interface/SimpleTransmission</type>
    <joint name="leg${suffix}joint2">
	      <hardwareInterface>EffortJointInterface</hardwareInterface>
    </joint>
    <actuator name="motor2">
      <hardwareInterface>EffortJointInterface</hardwareInterface>
      <mechanicalReduction>1</mechanicalReduction>
    </actuator>
  </transmission>
  <transmission name="tran3">
    <type>transmission_interface/SimpleTransmission</type>
    <joint name="leg${suffix}joint3">
	      <hardwareInterface>EffortJointInterface</hardwareInterface>
    </joint>
    <actuator name="motor3">
      <hardwareInterface>EffortJointInterface</hardwareInterface>
      <mechanicalReduction>1</mechanicalReduction>
    </actuator>
  </transmission>
  <transmission name="tran4">
    <type>transmission_interface/SimpleTransmission</type>
    <joint name="leg${suffix}joint4">
	      <hardwareInterface>EffortJointInterface</hardwareInterface>
    </joint>
    <actuator name="motor4">
      <hardwareInterface>EffortJointInterface</hardwareInterface>
      <mechanicalReduction>1</mechanicalReduction>
    </actuator>
  </transmission>
  <transmission name="tran5">
    <type>transmission_interface/SimpleTransmission</type>
    <joint name="leg${suffix}joint5">
	      <hardwareInterface>EffortJointInterface</hardwareInterface>
    </joint>
    <actuator name="motor5">
      <hardwareInterface>EffortJointInterface</hardwareInterface>
      <mechanicalReduction>1</mechanicalReduction>
    </actuator>
  </transmission>
    		
	</macro>
</robot>

