<?xml version='1.0'?>
<robot name="daedalus" xmlns:xacro="http://www.ros.org/wiki/xacro">    

<!-- Import Rviz colors -->
  <xacro:include filename="$(find daedalus_description)/urdf/materials.xacro" />

<!-- Import all Gazebo-customization elements, including Gazebo colors -->
  <xacro:include filename="$(find daedalus_description)/urdf/daedalus.gazebo" />
  

  <gazebo>
    <plugin name="gazebo_ros_control" filename="libgazebo_ros_control.so">
      <robotNamespace>/rrbot</robotNamespace>
    </plugin>
  </gazebo>
  

  
  <transmission name="tran1">
    <type>transmission_interface/SimpleTransmission</type>
    <joint name="leg1joint1">
	      <hardwareInterface>EffortJointInterface</hardwareInterface>
    </joint>
    <actuator name="motor1">
      <hardwareInterface>EffortJointInterface</hardwareInterface>
      <mechanicalReduction>1</mechanicalReduction>
    </actuator>
  </transmission>
  <transmission name="tran2">
    <type>transmission_interface/SimpleTransmission</type>
    <joint name="leg1joint2">
	      <hardwareInterface>EffortJointInterface</hardwareInterface>
    </joint>
    <actuator name="motor2">
      <hardwareInterface>EffortJointInterface</hardwareInterface>
      <mechanicalReduction>1</mechanicalReduction>
    </actuator>
  </transmission>
  <transmission name="tran3">
    <type>transmission_interface/SimpleTransmission</type>
    <joint name="leg1joint3">
	      <hardwareInterface>EffortJointInterface</hardwareInterface>
    </joint>
    <actuator name="motor3">
      <hardwareInterface>EffortJointInterface</hardwareInterface>
      <mechanicalReduction>1</mechanicalReduction>
    </actuator>
  </transmission>
  <transmission name="tran4">
    <type>transmission_interface/SimpleTransmission</type>
    <joint name="leg1joint4">
	      <hardwareInterface>EffortJointInterface</hardwareInterface>
    </joint>
    <actuator name="motor4">
      <hardwareInterface>EffortJointInterface</hardwareInterface>
      <mechanicalReduction>1</mechanicalReduction>
    </actuator>
  </transmission>
  <transmission name="tran5">
    <type>transmission_interface/SimpleTransmission</type>
    <joint name="leg1joint5">
	      <hardwareInterface>EffortJointInterface</hardwareInterface>
    </joint>
    <actuator name="motor5">
      <hardwareInterface>EffortJointInterface</hardwareInterface>
      <mechanicalReduction>1</mechanicalReduction>
    </actuator>
  </transmission>
  	
  	<link name="world"/>
  	
	<joint type="fixed" name="base">
      <origin xyz="0 0 0" rpy="0 0 0"/>
      <child link="chasis"/>
      <parent link="world"/>
    </joint>
  	
    <link name="chasis">
      <inertial>
        <origin xyz="0 0 0.1" rpy="0 0 0"/>
        <mass value="0"/>
        <inertia ixx="0.083" ixy="0.083" ixz="0.083" iyy="0.083" iyz="0.083" izz="0.083"/>
      </inertial>
      <collision name="collision">
        <origin xyz="0 0 0.1" rpy="0 0 0"/>
        <geometry>
          <box size="0.25 0.25 0.2"/>
        </geometry>
      </collision>
       <visual name="visual">
        <origin xyz="0 0 0.1" rpy="0 0\ 0"/>
        <geometry>
          <box size="0.25 0.25 0.2"/>
        </geometry>
       </visual>
    </link>
    <link name="leg1link0">
      <inertial>
        <origin xyz="0.892683838 1.03151079 0.148531107" rpy="0 0 0"/>
          <mass value="0.472639954"/>
        <inertia ixx="3.76702192" ixy="0" ixz="0" iyy="5.02939053" iyz="0" izz="0.104767786"/>
      </inertial>
      <collision name="collision">
        <origin xyz="0.892683838 1.03151079 0.148531107" rpy="0 0 0"/>
        <geometry>
          <mesh filename="package://daedalus_description/meshes/link0.dae"/>
        </geometry>
      </collision>
      <visual name="visual">
        <origin xyz="0.892683838 1.03151079 0.148531107" rpy="0 0 0"/>
        <geometry>
          <mesh filename="package://daedalus_description/meshes/link0.dae"/>
        </geometry>
      </visual>
    </link>
    <link name="leg1link1">
      <inertial>
        <origin xyz="0.837170246 1.0317214 0.161524277" rpy="0 0 0"/>
        <mass value="0.623121787"/>
        <inertia ixx="4.36786663" ixy="0" ixz="0" iyy="6.63326988" iyz="0" izz="0.164683289"/>
      </inertial>
      <collision name="collision">
        <origin xyz="-0.86 -1.03 -0.17" rpy="0 0 0"/>
        <geometry>
          <mesh filename="package://daedalus_description/meshes/link1.dae"/>
        </geometry>
      </collision>
      <visual name="visual">
        <origin xyz="-0.86 -1.03 -0.17" rpy="0 0 0"/>
        <geometry>
          <mesh filename="package://daedalus_description/meshes/link1.dae"/>
        </geometry>
      </visual>
    </link> 
    <link name="leg1link2">
      <self_collide>1</self_collide>
      <inertial>
        <origin xyz="-0.017799314 0.04493617  -0.002242117" rpy="0 0 0"/>
        <mass value="0.732147232"/>
        <inertia ixx="5.071313" ixy="0" ixz="0" iyy="8.46231008" iyz="0" izz="0.316663829"/>
      </inertial>
      <collision name="collision">
        <origin xyz="-0.85 -1.03 -0.21" rpy="0 0 0"/>
        <geometry>
          <mesh filename="package://daedalus_description/meshes/link2.dae"/>
        </geometry>
      </collision>
      <visual name="visual">
        <origin xyz="-0.85 -1.03 -0.21" rpy="0 0 0"/>
        <geometry>
          <mesh filename="package://daedalus_description/meshes/link2.dae"/>
        </geometry>
      </visual>
    </link>
    <link name="leg1link3">
      <self_collide>1</self_collide>
      <inertial>
        <origin xyz=" -0.0177993  -0.0027828  -0.0402923" rpy="0 0 0"/>
        <mass value="0.431132052"/>
        <inertia ixx="2.98629222" ixy="0" ixz="0" iyy="5.09630234" iyz="0" izz="0.0982604921"/>
      </inertial>
      <collision name="collision">
        <origin xyz="-0.85 -1.09 -0.19" rpy="0 0 0"/>
        <geometry>
          <mesh filename="package://daedalus_description/meshes/link3.dae"/>
        </geometry>
      </collision>
      <visual name="visual">
        <origin xyz="-0.85 -1.09 -0.19" rpy="0 0 0"/>
        <geometry>
          <mesh filename="package://daedalus_description/meshes/link3.dae"/>
        </geometry>
      </visual>
    </link>
    <link name="leg1link4">
      <self_collide>1</self_collide>
      <inertial>
        <origin xyz="0.0230260  -0.0192363  -0.0096265" rpy="0 0 0"/>
        <mass value="0.790197358"/>
        <inertia ixx="5.48411837" ixy="0" ixz="0" iyy="8.72903423" iyz="0" izz="0.0812723132"/>
      </inertial>
      <collision name="collision">
        <origin xyz="-0.81 -1.07 -0.11" rpy="0 0 0"/>
        <geometry>
          <mesh filename="package://daedalus_description/meshes/link4.dae"/>
        </geometry>
      </collision>
      <visual name="visual">
        <origin xyz="-0.81 -1.07 -0.11" rpy="0 0 0"/>
        <geometry>
          <mesh filename="package://daedalus_description/meshes/link4.dae"/>
        </geometry>
      </visual>
    </link>
    <link name="leg1link5">
      <self_collide>1</self_collide>
      <inertial>
        <origin xyz="0.0019165   0.0104236  -0.0496145" rpy="0 0 0"/>
        <mass value="0.655679875"/>
        <inertia ixx="4.53905844" ixy="0" ixz="0" iyy="7.09980012" iyz="0" izz="0.012361989"/>
      </inertial>
      <collision name="collision">
        <origin xyz="-0.83 -1.03 -0.09" rpy="0 0 0"/>
        <geometry>
          <mesh filename="package://daedalus_description/meshes/link5.dae"/>
        </geometry>
      </collision>
      <visual name="visual">
        <origin xyz="-0.83 -1.03 -0.09" rpy="0 0 0"/>
        <geometry>
          <mesh filename="package://daedalus_description/meshes/link5.dae"/>
        </geometry>
      </visual>
    </link>
    <joint type="fixed" name="leg1joint0">
      <origin xyz="-1.035 -1.125 0" rpy="0 0 0"/>
      <child link="leg1link0"/>
      <parent link="chasis"/>
      <axis xyz="1 0 0"/>
    </joint>
    <joint type="revolute" name="leg1joint1">
      <origin xyz="0.86 1.03 0.17" rpy="0 0 0"/>
      <child link="leg1link1"/>
      <parent link="leg1link0"/>"
      <axis xyz="0 0 1"/>
      <limit lower="-1.57" upper="1.57" effort="100" velocity="0.5"/>
    </joint>
    <joint type="revolute" name="leg1joint2">
      <origin xyz="-0.01 0 0.04" rpy="0 0 0"/>
      <child link="leg1link2"/>
      <parent link="leg1link1"/>
      <axis xyz="1 0 0"/>
      <limit lower="-0.45" upper="3.59" effort="100" velocity="0.5"/>
    </joint>
    <joint type="revolute" name="leg1joint3">
      <origin xyz="0 0.06 -0.02" rpy="0 0 0"/>
      <child link="leg1link3"/>
      <parent link="leg1link2"/>
      <axis xyz="1 0 0"/>
      <limit lower="-1.57" upper="1.57" effort="100" velocity="0.5"/>
    </joint>
    <joint type="revolute" name="leg1joint4">
      <origin xyz="-0.04 -0.02 -0.08" rpy="0 0 0"/>
      <child link="leg1link4"/>
      <parent link="leg1link3"/>
      <axis xyz="1 0 0"/>
      <limit lower="-1.57" upper="1.57" effort="100" velocity="0.5"/>
    </joint>
    <joint type="revolute" name="leg1joint5">
      <origin xyz="0.02 -0.04 -0.02" rpy="0 0 0"/>
      <child link="leg1link5"/>
      <parent link="leg1link4"/>
      <axis xyz="0 1 0"/>
      <limit lower="-1.57" upper="1.57" effort="100" velocity="0.5"/>
    </joint>
    <!-- <link name="leg2link0">
      <inertial>
        <origin xyz="0.892683838 1.03151079 0.148531107" rpy="0 0 0"/>
          <mass value="4.72639954"/>
        <inertia ixx="3.76702192" ixy="0" ixz="0" iyy="5.02939053" iyz="0" izz="0.104767786"/>
      </inertial>
      <collision name="collision">
        <origin xyz="0 0 0" rpy="0 0 0"/>
        <geometry>
          <mesh filename="package://daedalus_description/meshes/link0.dae"/>
        </geometry>
      </collision>
      <visual name="visual">
        <origin xyz="0 0 0" rpy="0 0 0"/>
        <geometry>
          <mesh filename="package://daedalus_description/meshes/link0.dae"/>
        </geometry>
      </visual>
    </link>
    <link name="leg2link1">
      <inertial>
        <origin xyz="0.837170246 1.0317214 0.161524277" rpy="0 0 0"/>
        <mass value="6.23121787"/>
        <inertia ixx="4.36786663" ixy="0" ixz="0" iyy="6.63326988" iyz="0" izz="0.164683289"/>
      </inertial>
      <collision name="collision">
        <origin xyz="-0.86 -1.03 -0.17" rpy="0 0 0"/>
        <geometry>
          <mesh filename="package://daedalus_description/meshes/link1.dae"/>
        </geometry>
      </collision>
      <visual name="visual">
        <origin xyz="-0.86 -1.03 -0.17" rpy="0 0 0"/>
        <geometry>
          <mesh filename="package://daedalus_description/meshes/link1.dae"/>
        </geometry>
      </visual>
    </link>  -->
    <!-- <link name="leg2link2">
      <self_collide>1</self_collide>
      <inertial>
        <origin xyz="-0.017799314 0.04493617  -0.002242117" rpy="0 0 0"/>
        <mass value="7.32147232"/>
        <inertia ixx="5.071313" ixy="0" ixz="0" iyy="8.46231008" iyz="0" izz="0.316663829"/>
      </inertial>
      <collision name="collision">
        <origin xyz="-0.85 -1.03 -0.21" rpy="0 0 0"/>
        <geometry>
          <mesh filename="package://daedalus_description/meshes/link2.dae"/>
        </geometry>
      </collision>
      <visual name="visual">
        <origin xyz="-0.85 -1.03 -0.21" rpy="0 0 0"/>
        <geometry>
          <mesh filename="package://daedalus_description/meshes/link2.dae"/>
        </geometry>
      </visual>
    </link> -->
    <!-- <link name="leg2link3">
      <self_collide>1</self_collide>
      <inertial>
        <origin xyz=" -0.0177993  -0.0027828  -0.0402923" rpy="0 0 0"/>
        <mass value="4.31132052"/>
        <inertia ixx="2.98629222" ixy="0" ixz="0" iyy="5.09630234" iyz="0" izz="0.0982604921"/>
      </inertial>
      <collision name="collision">
        <origin xyz="-0.85 -1.09 -0.19" rpy="0 0 0"/>
        <geometry>
          <mesh filename="package://daedalus_description/meshes/link3.dae"/>
        </geometry>
      </collision>
      <visual name="visual">
        <origin xyz="-0.85 -1.09 -0.19" rpy="0 0 0"/>
        <geometry>
          <mesh filename="package://daedalus_description/meshes/link3.dae"/>
        </geometry>
      </visual>
    </link>
    <link name="leg2link4">
      <self_collide>1</self_collide>
      <inertial>
        <origin xyz="0.0230260  -0.0192363  -0.0096265" rpy="0 0 0"/>
        <mass value="7.90197358"/>
        <inertia ixx="5.48411837" ixy="0" ixz="0" iyy="8.72903423" iyz="0" izz="0.0812723132"/>
      </inertial>
      <collision name="collision">
        <origin xyz="-0.81 -1.07 -0.11" rpy="0 0 0"/>
        <geometry>
          <mesh filename="package://daedalus_description/meshes/link4.dae"/>
        </geometry>
      </collision>
      <visual name="visual">
        <origin xyz="-0.81 -1.07 -0.11" rpy="0 0 0"/>
        <geometry>
          <mesh filename="package://daedalus_description/meshes/link4.dae"/>
        </geometry>
      </visual>
    </link>
    <link name="leg2link5">
      <self_collide>1</self_collide>
      <inertial>
        <origin xyz="0.0019165   0.0104236  -0.0496145" rpy="0 0 0"/>
        <mass value="6.55679875"/>
        <inertia ixx="4.53905844" ixy="0" ixz="0" iyy="7.09980012" iyz="0" izz="0.012361989"/>
      </inertial>
      <collision name="collision">
        <origin xyz="-0.83 -1.03 -0.09" rpy="0 0 0"/>
        <geometry>
          <mesh filename="package://daedalus_description/meshes/link5.dae"/>
        </geometry>
      </collision>
      <visual name="visual">
        <origin xyz="-0.83 -1.03 -0.09" rpy="0 0 0"/>
        <geometry>
          <mesh filename="package://daedalus_description/meshes/link5.dae"/>
        </geometry>
      </visual>
    </link> -->
    <!-- <joint type="fixed" name="leg2joint0">
      <origin xyz="-1.035 -0.925 0" rpy="0 0 0"/>
      <child link="leg2link0"/>
      <parent link="chasis"/>
      <axis xyz="1 0 0"/>
    </joint> -->
    <!-- <joint type="revolute" name="leg2joint1">
      <origin xyz="0.86 1.03 0.17" rpy="0 0 0"/>
      <child link="leg2link1"/>
      <parent link="leg2link0"/>"
      <axis xyz="0 0 1"/>
      <limit lower="-1.57" upper="1.57" effort="10" velocity="0.5"/>
    </joint> -->
    <!-- <joint type="revolute" name="leg2joint2">
      <origin xyz="-0.01 0 0.04" rpy="0 0 0"/>
      <child link="leg2link2"/>
      <parent link="leg2link1"/>
      <axis xyz="1 0 0"/>
      <limit lower="-0.45" upper="3.59" effort="10" velocity="0.5"/>
    </joint> -->
    <!-- <joint type="revolute" name="leg2joint3">
      <origin xyz="0 0.06 -0.02" rpy="0 0 0"/>
      <child link="leg2link3"/>
      <parent link="leg2link2"/>
      <axis xyz="1 0 0"/>
      <limit lower="-1.57" upper="1.57" effort="10" velocity="0.5"/>
    </joint>
    <joint type="revolute" name="leg2joint4">
      <origin xyz="-0.04 -0.02 -0.08" rpy="0 0 0"/>
      <child link="leg2link4"/>
      <parent link="leg2link3"/>
      <axis xyz="1 0 0"/>
      <limit lower="-1.57" upper="1.57" effort="10" velocity="0.5"/>
    </joint>
    <joint type="revolute" name="leg2joint5">
      <origin xyz="0.02 -0.04 -0.02" rpy="0 0 0"/>
      <child link="leg2link5"/>
      <parent link="leg2link4"/>
      <axis xyz="0 1 0"/>
      <limit lower="-1.57" upper="1.57" effort="10" velocity="0.5"/>
    </joint> -->
</robot>
